Workbook

Sheet 저축 구리두리
A1: 기준일 | B1: 입금액 | C1: 마통잔액 | D1: 인출가능 금액 | E1: 달성 여부 | F1: 정리 | H1: 차수 | I1: 입금일 | J1: 필요금액 | K1: 누적 목표
A2: 46142 | B2: 4110000 | C2: -63769347 | D2: 6530653 | E2: =IF(D2>=$K$3,"6차 달성",IF(D2>=$K$2,"5차 달성","미달성")) -> 미달성 | F2: =IF(D2>=$K$3, "완료", IF(D2>=$K$2, $H$3&" "&TEXT($K$3-D2,"#,##0")&"원 필요 / "&IF(A2>$I$3,"목표일 경과",DATEDIF(A2,$I$3,"M")&"개월 남음"), $H$2&" "&TEXT($K$2-D2,"#,##0")&"원 필요 / "&IF(A2>$I$2,"목표일 경과",DATEDIF(A2,$I$2,"M")&"개월 남음") ) ) -> 5차 68,989,347원 필요 / 19개월 남음 | H2: 5차 | I2: 46731 | J2: 75520000 | K2: 75520000
H3: 6차 | I3: 46822 | J3: 75520000 | K3: 151040000
H7: 짜바리
H8: 엔화 40만원
H9: MS 370만원
H10: 청약 910
H11: 1320
H12: 450

Sheet 요약
B2: 자동연동
B3: 2026 | D3: 총 저축액 | E3: 1월 | F3: 2월 | G3: 3월 | H3: 4월 | I3: 5월 | J3: 6월 | K3: 7월 | L3: 8월 | M3: 9월 | N3: 10월 | O3: 11월 | P3: 12월
D4: =SUM(E4:P4) -> 11003829 | E4: =E21 -> 0 | F4: =F21 -> 5659810 | G4: =G21 -> 5344019 | H4: =H21 -> 0 | I4: =I21 -> 0 | J4: =J21 -> 0 | K4: =K21 -> 0 | L4: =L21 -> 0 | ... P4: =P21 -> 0
B6: 구분 | E6: 1월 | F6: 2월 | G6: 3월 | H6: 4월 | I6: 5월 | J6: 6월 | K6: 7월 | L6: 8월 | M6: 9월 | N6: 10월 | O6: 11월 | P6: 12월 | R6: 신용은 이달에 쓴 것 기준
B7: 수입 | E7: ='1월'!$C6 -> 0 | F7: ='2월'!$C6 -> 11435984 | G7: ='3월'!$C6 -> 7781153 | H7: ='4월'!$C6 -> 1474591 | I7: ='5월'!$C6 -> 0 | J7: ='6월'!$C6 -> 0 | K7: ='7월'!$C6 -> 0 | L7: ='8월'!$C6 -> 0 | M7: ='9월'!$C6 -> 0 | N7: ='10월'!$C6 -> 0 | O7: ='11월'!$C6 -> 0 | P7: ='12월'!$C6 -> 0 | R7: 나머지는 부과된 날 기준
B8: 지출 | C8: 고정비 | E8: ='1월'!$H$13 -> 0 | F8: ='2월'!$H$13 -> 2533238 | G8: ='3월'!$H$13 -> 2007103 | H8: ='4월'!$H$13 -> 618393 | I8: ='5월'!$H$13 -> 0 | J8: ='6월'!$H$13 -> 0 | K8: ='7월'!$H$13 -> 0 | L8: ='8월'!$H$13 -> 0 | M8: ='9월'!$H$13 -> 0 | N8: ='10월'!$H$13 -> 0 | O8: ='11월'!$H$13 -> 0 | P8: ='12월'!$H$13 -> 0
C9: 변동비 | E9: ='1월'!$I$13 -> 0 | F9: ='2월'!$I$13 -> 1128167 | G9: ='3월'!$I$13 -> 1200000 | H9: ='4월'!$I$13 -> 1450000 | I9: ='5월'!$I$13 -> 0 | J9: ='6월'!$I$13 -> 0 | K9: ='7월'!$I$13 -> 0 | L9: ='8월'!$I$13 -> 0 | M9: ='9월'!$I$13 -> 0 | N9: ='10월'!$I$13 -> 0 | O9: ='11월'!$I$13 -> 0 | P9: ='12월'!$I$13 -> 0
B10: 지출 합계 | E10: =SUM(E8:E9) -> 0 | F10: =SUM(F8:F9) -> 3661405 | G10: =SUM(G8:G9) -> 3207103 | H10: =SUM(H8:H9) -> 2068393 | I10: =SUM(I8:I9) -> 0 | J10: =SUM(J8:J9) -> 0 | K10: =SUM(K8:K9) -> 0 | L10: =SUM(L8:L9) -> 0 | ... P10: =SUM(P8:P9) -> 0
B11: 저축 | C11: 민정 청약 | E11: ='1월'!$E6 -> 0 | F11: ='2월'!$E6 -> 250000 | G11: ='3월'!$E6 -> 250000 | H11: ='4월'!$E6 -> 0 | I11: ='5월'!$E6 -> 0 | J11: ='6월'!$E6 -> 0 | K11: ='7월'!$E6 -> 0 | L11: ='8월'!$E6 -> 0 | M11: ='9월'!$E6 -> 0 | N11: ='10월'!$E6 -> 0 | O11: ='11월'!$E6 -> 0 | P11: ='12월'!$E6 -> 0
C12: 상휘 청약 | E12: ='1월'!$F6 -> 0 | F12: ='2월'!$F6 -> 100000 | G12: ='3월'!$F6 -> 100000 | H12: ='4월'!$F6 -> 0 | I12: ='5월'!$F6 -> 0 | J12: ='6월'!$F6 -> 0 | K12: ='7월'!$F6 -> 0 | L12: ='8월'!$F6 -> 0 | M12: ='9월'!$F6 -> 0 | N12: ='10월'!$F6 -> 0 | O12: ='11월'!$F6 -> 0 | P12: ='12월'!$F6 -> 0
C13: 민정 퇴직연금 | E13: ='1월'!$G6 -> 0 | F13: ='2월'!$G6 -> 100000 | G13: ='3월'!$G6 -> 100000 | H13: ='4월'!$G6 -> 0 | I13: ='5월'!$G6 -> 0 | J13: ='6월'!$G6 -> 0 | K13: ='7월'!$G6 -> 0 | L13: ='8월'!$G6 -> 0 | M13: ='9월'!$G6 -> 0 | N13: ='10월'!$G6 -> 0 | O13: ='12월'!$G6 -> 0 | P13: ='12월'!$G6 -> 0
C14: 상휘 청년내일 | E14: ='1월'!$H6 -> 0 | F14: ='2월'!$H6 -> 100000 | G14: ='3월'!$H6 -> 100000 | H14: ='4월'!$H6 -> 0 | I14: ='5월'!$H6 -> 0 | J14: ='6월'!$H6 -> 0 | K14: ='7월'!$H6 -> 0 | L14: ='8월'!$H6 -> 0 | M14: ='9월'!$H6 -> 0 | N14: ='10월'!$H6 -> 0 | O14: ='11월'!$H6 -> 0 | P14: ='12월'!$H6 -> 0
C15: 상휘 금계좌 | E15: ='1월'!$I6 -> 0 | F15: ='2월'!$I6 -> 200000 | G15: ='3월'!$I6 -> 200000 | H15: ='4월'!$I6 -> 0 | I15: ='5월'!$I6 -> 0 | J15: ='6월'!$I6 -> 0 | K15: ='7월'!$I6 -> 0 | L15: ='8월'!$I6 -> 0 | M15: ='9월'!$I6 -> 0 | N15: ='10월'!$I6 -> 0 | O15: ='11월'!$I6 -> 0 | P15: ='12월'!$I6 -> 0
C16: 상휘 마통 상환 | E16: ='1월'!$J6 -> 0 | F16: ='2월'!$J6 -> 4909810 | G16: ='3월'!$J6 -> 4594019 | H16: ='4월'!$J6 -> 0 | I16: ='5월'!$J6 -> 0 | J16: ='6월'!$J6 -> 0 | K16: ='7월'!$J6 -> 0 | L16: ='8월'!$J6 -> 0 | M16: ='9월'!$J6 -> 0 | N16: ='10월'!$J6 -> 0 | O16: ='11월'!$J6 -> 0 | P16: ='12월'!$J6 -> 0
E17: ='1월'!$K6 -> 0 | F17: ='2월'!$K6 -> 0 | G17: ='3월'!$K6 -> 0 | H17: ='4월'!$K6 -> 0 | I17: ='5월'!$K6 -> 0 | J17: ='6월'!$K6 -> 0 | K17: ='7월'!$K6 -> 0 | L17: ='8월'!$K6 -> 0 | M17: ='9월'!$K6 -> 0 | N17: ='10월'!$K6 -> 0 | O17: ='11월'!$K6 -> 0 | P17: ='12월'!$K6 -> 0
E18: ='1월'!$L6 -> 0 | F18: ='2월'!$L6 -> 0 | G18: ='3월'!$L6 -> 0 | H18: ='4월'!$L6 -> 0 | I18: ='5월'!$L6 -> 0 | J18: ='6월'!$L6 -> 0 | K18: ='7월'!$L6 -> 0 | L18: ='8월'!$L6 -> 0 | M18: ='9월'!$L6 -> 0 | N18: ='10월'!$L6 -> 0 | O18: ='11월'!$L6 -> 0 | P18: ='12월'!$L6 -> 0
E19: ='1월'!$M6 -> 0 | F19: ='2월'!$M6 -> 0 | G19: ='3월'!$M6 -> 0 | H19: ='4월'!$M6 -> 0 | I19: ='5월'!$M6 -> 0 | J19: ='6월'!$M6 -> 0 | K19: ='7월'!$M6 -> 0 | L19: ='8월'!$M6 -> 0 | M19: ='9월'!$M6 -> 0 | N19: ='10월'!$M6 -> 0 | O19: ='11월'!$M6 -> 0 | P19: ='12월'!$M6 -> 0
E20: ='1월'!$N6 -> 0 | F20: ='2월'!$N6 -> 0 | G20: ='3월'!$N6 -> 0 | H20: ='4월'!$N6 -> 0 | I20: ='5월'!$N6 -> 0 | J20: ='6월'!$N6 -> 0 | K20: ='7월'!$N6 -> 0 | L20: ='8월'!$N6 -> 0 | M20: ='9월'!$N6 -> 0 | N20: ='10월'!$N6 -> 0 | O20: ='11월'!$N6 -> 0 | P20: ='12월'!$N6 -> 0
B21: 저축 합계 | E21: =SUM(E11:E20) -> 0 | F21: =SUM(F11:F20) -> 5659810 | G21: =SUM(G11:G20) -> 5344019 | H21: =SUM(H11:H20) -> 0 | I21: =SUM(I11:I20) -> 0 | J21: =SUM(J11:J20) -> 0 | K21: =SUM(K11:K20) -> 0 | L21: =SUM(L11:L20) -> 0 | ... P21: =SUM(P11:P20) -> 0
B22: 특이사항 | C22: 지출예정 | F22: 타이어(변동비) | I22: 어버이날 | M22: 추석

Sheet 1월
E2: 직접입력 | F2: 직접동일입력 | G2: 그 외 자동 연동 | P2: 계획
B4: 요약 | E4: 저축
B5: 이월잔액 | C5: =C13 -> 0
B6: 수입 | C6: =E13 -> 0
B7: 지출 | C7: =H13+I13 -> 0
B8: 잔액 | C8: =C5+C6-C7-E7 -> 0
B10: 구분 | C10: 이월잔액 | E10: 수입 | H10: 지출
C11: 계좌1 | D11: 계좌2 | E11: 주수입 | F11: 기타 | G11: 기타비고 | H11: 고정비 | I11: 계좌(비고정) | J11: 카드(비고정)
B12: 금액
B13: 합계
B15: 카드별 지출 요약
B16: 카드명 | C16: 일시불 | D16: 할부 | E16: 합계
B17: 하나 알뜰 체크
B18: 하나 신용
B19: 현대 신용
B20: 하나 시코르
B21: 합계
B23: 고정 지출
B24: 구분 | C24: 분류 | D24: 항목 | E24: 지출
B25: 고정비
B40: 합계 | E40: =SUM(E25:E39) -> 0
B42: 지출 - 신용카드 할부
B43: 회차 | C43: 항목 | D43: 금액 | E43: 지불방식 | F43: 잔액 | G43: 잔여회차 | H43: 총 회차
G44: =H44-B44 -> 0
G45: =H45-B45 -> 0
B48: 할부 합계 | D48: =SUM(D44:D47) -> 0 | E48: 할부 잔액 | F48: =SUM(F44:F47) -> 0
B50: 지출 - 비고정비
B51: 날짜 | C51: 항목 | D51: 지불 내용 | E51: 금액 | F51: 지불방식
B52: 비고정비 합계 | F52: 카드 OR 계좌 | G52: 비고
B53: 45326 | C53: 구매 | D53: 로봇 청소기 | E53: 500000 | F53: 계좌
B54: 45333 | C54: 설 용돈 | D54: 엄마 | E54: 300000 | F54: 계좌
B55: 45346 | C55: 축의금 | D55: 윤혜 언니 | E55: 100000 | F55: 계좌
B56: 45349 | C56: 운전교육 | D56: 기능 추가 교육 | E56: 120000 | F56: 계좌

Sheet 2월
B2: 2월 25일 ~ 3월 24일 | E2: 직접입력 | F2: 직접동일입력 | G2: 그 외 자동 연동
B4: 요약 | E4: 저축
B5: 이월잔액 | C5: =C13 -> 567331 | E5: 민정 청약 | F5: 상휘 청약 | G5: 민정 퇴직연금 | H5: 상휘 청년내일 | I5: 상휘 금계좌 | J5: 상휘 마통
B6: 수입 | C6: =E13 -> 11435984 | E6: 250000 | F6: 100000 | G6: 100000 | H6: 100000 | I6: 200000 | J6: 4909810
B7: 지출 | C7: =H13+I13 -> 3661405 | E7: =SUM(E6:J6) -> 5659810
B8: 잔액 | C8: =C5+C6-C7-E7 -> 2682100
E9: 이번달은 연말정산 들어온 것
B10: 구분 | C10: 이월잔액 | E10: 수입 | H10: 지출
C11: 토스모임 | D11: 계좌2 | E11: 민정 | F11: 상휘 | G11: 기타비고 | H11: 고정비 | I11: 계좌(비고정) | J11: 카드(비고정)
B12: 금액 | C12: 567331 | D12: 0 | E12: 6526174 | F12: 4909810 | H12: =E42 -> 2533238 | I12: =SUMIF(F55:F1063,"계좌",E55:E1063) -> 743000 | J12: =E21 -> 385167
B13: 합계 | C13: =SUM(C12:D12) -> 567331 | E13: =SUM(E12:G12) -> 11435984 | H13: =SUM(H12) -> 2533238 | I13: =SUM(I12:J12) -> 1128167
B15: 카드별 지출 요약
B16: 카드명 | C16: 일시불 | D16: 할부 | E16: 합계 | F16: 카드 사용 기간이 2월인 것 (결제는 3월 중순)
B17: 민정 하나 신용 | C17: 376067 | D17: =SUMIF(E$46:E$48,B17,D$46:D$49) -> 0 | E17: =SUM(C17:D17) -> 376067
B18: 민정 현대 신용 | D18: =SUMIF(E$46:E$48,B18,D$46:D$49) -> 0 | E18: =SUM(C18:D18) -> 0
B19: 상휘 하나 신용 | D19: =SUMIF(E$46:E$48,B19,D$46:D$49) -> 0 | E19: =SUM(C19:D19) -> 0 | F19: 주유, 경점검, 톨비로 40만원 예산
B20: 상휘 현대 신용 | C20: 9100 | D20: =SUMIF(E$46:E$48,B20,D$46:D$49) -> 0 | E20: =SUM(C20:D20) -> 9100
B21: 합계 | C21: =SUM(C17:C20) -> 385167 | D21: =SUM(D17:D20) -> 0 | E21: =SUM(E17:E20) -> 385167
B23: 고정 지출 | F23: 미리
B24: 구분 | C24: 분류 | D24: 항목 | E24: 실제 지출 | F24: 예상
B25: 고정비 | C25: 주거 | D25: 버팀목 이자 | E25: 140380 | F25: 155420
C26: 주거 | D26: 중기청 이자 | E26: 112100 | F26: 112199
C27: 통신 | D27: 휴대폰 - 민정 | E27: 32970 | F27: 32970
C28: 통신 | D28: 휴대폰 - 상휘 | E28: 119800 | F28: 60800 | G28: 신혼여행 로밍
C29: 통신 | D29: 인터넷 | E29: 23100 | F29: 23100
C30: 보험 | D30: KB 손보 - 민정 | E30: 100089 | F30: 100089
C31: 보험 | D31: 농협 손보 - 민정 | E31: 53105 | F31: 53105
C32: 보험 | D32: DB 손보 - 상휘 | E32: 21070 | F32: 21070
C33: 보험 | D33: 삼성일반 - 상휘 | E33: 52840 | F33: 52840
C34: 보험 | D34: 삼성손보 - 상휘 | E34: 18014 | F34: 18014
C35: 구독 | D35: 넷플릭스 | E35: 8375 | F35: 8375
C36: 친목 | D36: 민정 친구 곗돈 | E36: 70000 | F36: 70000
C37: 기타 | D37: 민정 본가 용돈 | E37: 300000 | F37: 300000
C38: 주거 | D38: 관리비 | E38: 463070 | F38: 463070
C39: 주거 | D39: 가스비 | E39: 0 | F39: 10420 | G39: 3개월마다
C40: 교통 | D40: 민정 대중교통비 | E40: 39750 | F40: 90000 | G40: 신혼여행으로 대중교통 덜 이용, 보통 13만원 - K패스환급 4만원
C41: 기타 | D41: 생활비 | E41: 978575 | F41: 600000 | G41: 기타 생활비 | H41: 용돈을 38만원 더 씀
B42: 합계 | E42: =SUM(E25:E41) -> 2533238 | F42: =SUM(F25:F41) -> 2171472
B44: 지출 - 신용카드 할부
B45: 회차 | C45: 항목 | D45: 금액 | E45: 지불방식 | F45: 잔액 | G45: 잔여회차 | H45: 총 회차
...

Sheet 3월
B1: 3월 25일 ~ 4월 24일
E2: 직접입력 | F2: 직접동일입력 | G2: 그 외 자동 연동 | P2: 계획
P3: 토스 비고정비 계좌 | Q3: =E54 -> 500000
B4: 요약 | E4: 저축 | P4: 토스 자유 입출금 | Q4: =SUM(E6:I6,C21,E42) -> 3457103
B5: 이월잔액 | C5: =C13 -> 894019 | E5: 민정 청약 | F5: 상휘 청약 | G5: 민정 퇴직연금 | H5: 상휘 청년내일 | I5: 상휘 금계좌 | J5: 상휘 마통
B6: 수입 | C6: =E13 -> 7781153 | E6: 250000 | F6: 100000 | G6: 100000 | H6: 100000 | I6: 200000 | J6: 4594019
B7: 지출 | C7: =H13+I13 -> 3207103 | E7: =SUM(E6:J6) -> 5344019
B8: 잔액 | C8: =C5+C6-C7-E7 -> 124050
E9: 이번달은 연말정산 들어온 것
B10: 구분 | C10: 이월잔액 | E10: 수입 | H10: 지출
C11: 토스모임 | D11: 계좌2 | E11: 민정 | F11: 상휘 | G11: 기타비고 | H11: 고정비 | I11: 계좌(비고정) | J11: 카드(비고정)
B12: 금액 | C12: 894019 | D12: 0 | E12: 4081153 | F12: 3700000 | H12: =E42 -> 2007103 | I12: =SUMIF(F55:F1063,"계좌",E55:E1063) -> 500000 | J12: =E21 -> 700000
B13: 합계 | C13: =SUM(C12:D12) -> 894019 | E13: =SUM(E12:G12) -> 7781153 | H13: =SUM(H12) -> 2007103 | I13: =SUM(I12:J12) -> 1200000
B15: 카드별 지출 요약
B16: 카드명 | C16: 일시불 | D16: 할부 | E16: 합계 | F16: 카드 사용 기간이 3월인 것 (결제는 4월 중순)
B17: 민정 하나 신용 | C17: 60000 | D17: =SUMIF(E$46:E$48,B17,D$46:D$49) -> 0 | E17: =SUM(C17:D17) -> 60000 | F17: 복지카드 차감제외하면 6만원정도
B18: 민정 현대 신용 | C18: 240000 | D18: =SUMIF(E$46:E$48,B18,D$46:D$49) -> 0 | E18: =SUM(C18:D18) -> 240000 | F18: 도쿄 항공 취소
B19: 상휘 하나 신용 | C19: 400000 | D19: =SUMIF(E$46:E$48,B19,D$46:D$49) -> 0 | E19: =SUM(C19:D19) -> 400000 | F19: 주유, 경점검, 톨비로 40만원 예산
B20: 상휘 현대 신용 | D20: =SUMIF(E$46:E$48,B20,D$46:D$49) -> 0 | E20: =SUM(C20:D20) -> 0
B21: 합계 | C21: =SUM(C17:C20) -> 700000 | D21: =SUM(D17:D20) -> 0 | E21: =SUM(E17:E20) -> 700000
B23: 고정 지출 | F23: 미리
B24: 구분 | C24: 분류 | D24: 항목 | E24: 실제 지출 | F24: 예상
B25: 고정비 | C25: 주거 | D25: 버팀목 이자 | E25: 140380 | F25: 140380
C26: 주거 | D26: 중기청 이자 | E26: 112100 | F26: 112100
C27: 통신 | D27: 휴대폰 - 민정 | E27: 32970 | F27: 32970
C28: 통신 | D28: 휴대폰 - 상휘 | E28: 60800 | F28: 60800
C29: 통신 | D29: 인터넷 | E29: 23100 | F29: 23100
C30: 보험 | D30: KB 손보 - 민정 | E30: 100089 | F30: 100089
C31: 보험 | D31: 농협 손보 - 민정 | E31: 53105 | F31: 53105
C32: 보험 | D32: DB 손보 - 상휘 | E32: 21070 | F32: 21070
C33: 보험 | D33: 삼성일반 - 상휘 | E33: 52840 | F33: 52840
C34: 보험 | D34: 삼성손보 - 상휘 | E34: 18014 | F34: 18014
C35: 구독 | D35: 넷플릭스 | E35: 8375 | F35: 8375
C36: 친목 | D36: 민정 친구 곗돈 | E36: 70000 | F36: 70000
C37: 기타 | D37: 민정 본가 용돈 | E37: 300000 | F37: 300000
C38: 주거 | D38: 관리비 | E38: 324260 | F38: 324260
C39: 주거 | D39: 가스비 | E39: 0 | F39: 0 | G39: 3개월마다
C40: 교통 | D40: 민정 대중교통비 | E40: 90000 | F40: 90000
C41: 기타 | D41: 생활비 | E41: 600000 | F41: 600000 | G41: 기타 생활비
B42: 합계 | E42: =SUM(E25:E41) -> 2007103 | F42: =SUM(F25:F41) -> 2007103
...

Sheet 4월
B1: 4월 25일 ~ 5월 24일
E2: 직접입력 | F2: 직접동일입력 | G2: 그 외 자동 연동 | P2: 계획
P3: 토스 비고정비 계좌 | Q3: =E54 -> 750000
B4: 요약 | E4: 저축 | P4: 토스 자유 입출금 | Q4: =SUM(E6:I6,C21,E42) -> 1318393
B5: 이월잔액 | E5: 민정 청약 | F5: 상휘 청약 | G5: 민정 퇴직연금 | H5: 상휘 청년내일 | I5: 상휘MS | J5: 상휘 마통
B6: 수입 | C6: 1474591
B7: 지출 | C7: =H13+I13 -> 2068393 | E7: =SUM(E6:J6) -> 0
B8: 잔액 | C8: =C5+C6-C7-E7 -> -593802
E9: 이번달은 연말정산 들어온 것
B10: 구분 | C10: 이월잔액 | E10: 수입 | H10: 지출
C11: 토스모임 | D11: 계좌2 | E11: 민정 | F11: 상휘 | G11: 기타비고 | H11: 고정비 | I11: 계좌(비고정) | J11: 카드(비고정)
B12: 금액 | C12: 0 | D12: 0 | E12: 713166 | H12: =E42 -> 618393 | I12: =SUMIF(F55:F1063,"계좌",E55:E1063) -> 750000 | J12: =E21 -> 700000
B13: 합계 | C13: =SUM(C12:D12) -> 0 | E13: =SUM(E12:G12) -> 713166 | H13: =SUM(H12) -> 618393 | I13: =SUM(I12:J12) -> 1450000
B15: 카드별 지출 요약
B16: 카드명 | C16: 일시불 | D16: 할부 | E16: 합계 | F16: 카드 사용 기간이 4월인 것 (결제는 5월 중순)
B17: 민정 하나 신용 | C17: 100000 | D17: =SUMIF(E$46:E$48,B17,D$46:D$49) -> 0 | E17: =SUM(C17:D17) -> 100000 | F17: 본식앨범, 항공수수료 등
B18: 민정 현대 신용 | C18: 0 | D18: =SUMIF(E$46:E$48,B18,D$46:D$49) -> 0 | E18: =SUM(C18:D18) -> 0
B19: 상휘 하나 신용 | C19: 600000 | D19: =SUMIF(E$46:E$48,B19,D$46:D$49) -> 0 | E19: =SUM(C19:D19) -> 600000 | F19: 주유, 경점검, 톨비로 40만원 예산인데, 이번에 현금 중도금 이슈로 카드를 씀
B20: 상휘 현대 신용 | D20: =SUMIF(E$46:E$48,B20,D$46:D$49) -> 0 | E20: =SUM(C20:D20) -> 0
B21: 합계 | C21: =SUM(C17:C20) -> 700000 | D21: =SUM(D17:D20) -> 0 | E21: =SUM(E17:E20) -> 700000
J22: 민정 하나 | K22: 19
B23: 고정 지출 | F23: 미리
B24: 구분 | C24: 분류 | D24: 항목 | E24: 실제 지출 | F24: 예상 | J24: 자동이체 | K24: 62
B25: 고정비 | C25: 주거 | D25: 버팀목 이자 | E25: 140380 | F25: 140380 | J25: 비고정 | K25: 75
C26: 주거 | D26: 중기청 이자 | E26: 112100 | F26: 112100 | K26: 156
C27: 통신 | D27: 휴대폰 - 민정 | F27: 32970 | K27: 71
C28: 통신 | D28: 휴대폰 - 상휘 | E28: 60800 | F28: 60800 | K28: =K26-K27 -> 85
C29: 통신 | D29: 인터넷 | E29: 23100 | F29: 23100
C30: 보험 | D30: KB 손보 - 민정 | E30: 100089 | F30: 100089
C31: 보험 | D31: 농협 손보 - 민정 | F31: 53105
C32: 보험 | D32: DB 손보 - 상휘 | E32: 21070 | F32: 21070 | K32: 토스 : 85 만원 입금
C33: 보험 | D33: 삼성일반 - 상휘 | E33: 52840 | F33: 52840 | K33: 비고정비 75만원 넣기
C34: 보험 | D34: 삼성손보 - 상휘 | E34: 18014 | F34: 18014 | K34: 자동이체가 62만원 예정
C35: 구독 | D35: 넷플릭스 | F35: 8375
C36: 친목 | D36: 민정 친구 곗돈 | F36: 70000 | K36: 생활비, 상휘 하나카드는 고려 X
C37: 기타 | D37: 민정 본가 용돈 | F37: 300000
C38: 주거 | D38: 관리비 | F38: 0 | G38: 이번엔 저번달에 이미 냄
C39: 주거 | D39: 가스비 | F39: 0 | G39: 3개월마다
C40: 교통 | D40: 민정 대중교통비 | E40: 90000 | F40: 90000
C41: 기타 | D41: 생활비 | F41: 600000 | G41: 기타 생활비
...

Sheet 5월
E2: 직접입력 | F2: 직접동일입력 | G2: 그 외 자동 연동 | P2: 계획
B4: 요약 | E4: 저축
B5: 이월잔액 | C5: =C13 -> 0
B6: 수입 | C6: =E13 -> 0
B7: 지출 | C7: =H13+I13 -> 0
B8: 잔액 | C8: =C5+C6-C7-E7 -> 0
B10: 구분 | C10: 이월잔액 | E10: 수입 | H10: 지출
C11: 계좌1 | D11: 계좌2 | E11: 주수입 | F11: 기타 | G11: 기타비고 | H11: 고정비 | I11: 계좌(비고정) | J11: 카드(비고정)
B12: 금액
B13: 합계
B15: 카드별 지출 요약
B16: 카드명 | C16: 일시불 | D16: 할부 | E16: 합계
B17: 하나 알뜰 체크
B18: 하나 신용
B19: 현대 신용
B20: 하나 시코르
B21: 합계
B23: 고정 지출
B24: 구분 | C24: 분류 | D24: 항목 | E24: 지출
B25: 고정비
B40: 합계 | E40: =SUM(E25:E39) -> 0
B42: 지출 - 신용카드 할부
B43: 회차 | C43: 항목 | D43: 금액 | E43: 지불방식 | F43: 잔액 | G43: 잔여회차 | H43: 총 회차
G44: =H44-B44 -> 0
G45: =H45-B45 -> 0
B48: 할부 합계 | D48: =SUM(D44:D47) -> 0 | E48: 할부 잔액 | F48: =SUM(F44:F47) -> 0
B50: 지출 - 비고정비
B51: 날짜 | C51: 항목 | D51: 지불 내용 | E51: 금액 | F51: 지불방식
B52: 비고정비 합계 | F52: 카드 OR 계좌 | G52: 비고
B53: 45326 | C53: 구매 | D53: 로봇 청소기 | E53: 500000 | F53: 계좌
B54: 45333 | C54: 설 용돈 | D54: 엄마 | E54: 300000 | F54: 계좌
B55: 45346 | C55: 축의금 | D55: 윤혜 언니 | E55: 100000 | F55: 계좌
B56: 45349 | C56: 운전교육 | D56: 기능 추가 교육 | E56: 120000 | F56: 계좌

Sheet 6월
E2: 직접입력 | F2: 직접동일입력 | G2: 그 외 자동 연동 | P2: 계획
B4: 요약 | E4: 저축
B5: 이월잔액 | C5: =C13 -> 0
B6: 수입 | C6: =E13 -> 0
B7: 지출 | C7: =H13+I13 -> 0
B8: 잔액 | C8: =C5+C6-C7-E7 -> 0
B10: 구분 | C10: 이월잔액 | E10: 수입 | H10: 지출
C11: 계좌1 | D11: 계좌2 | E11: 주수입 | F11: 기타 | G11: 기타비고 | H11: 고정비 | I11: 계좌(비고정) | J11: 카드(비고정)
B12: 금액
B13: 합계
B15: 카드별 지출 요약
B16: 카드명 | C16: 일시불 | D16: 할부 | E16: 합계
B17: 하나 알뜰 체크
B18: 하나 신용
B19: 현대 신용
B20: 하나 시코르
B21: 합계
B23: 고정 지출
B24: 구분 | C24: 분류 | D24: 항목 | E24: 지출
B25: 고정비
B40: 합계 | E40: =SUM(E25:E39) -> 0
B42: 지출 - 신용카드 할부
B43: 회차 | C43: 항목 | D43: 금액 | E43: 지불방식 | F43: 잔액 | G43: 잔여회차 | H43: 총 회차
G44: =H44-B44 -> 0
G45: =H45-B45 -> 0
B48: 할부 합계 | D48: =SUM(D44:D47) -> 0 | E48: 할부 잔액 | F48: =SUM(F44:F47) -> 0
B50: 지출 - 비고정비
B51: 날짜 | C51: 항목 | D51: 지불 내용 | E51: 금액 | F51: 지불방식
B52: 비고정비 합계 | F52: 카드 OR 계좌 | G52: 비고
B53: 45326 | C53: 구매 | D53: 로봇 청소기 | E53: 500000 | F53: 계좌
B54: 45333 | C54: 설 용돈 | D54: 엄마 | E54: 300000 | F54: 계좌
B55: 45346 | C55: 축의금 | D55: 윤혜 언니 | E55: 100000 | F55: 계좌
B56: 45349 | C56: 운전교육 | D56: 기능 추가 교육 | E56: 120000 | F56: 계좌

Sheet 7월
E2: 직접입력 | F2: 직접동일입력 | G2: 그 외 자동 연동 | P2: 계획
B4: 요약 | E4: 저축
B5: 이월잔액 | C5: =C13 -> 0
B6: 수입 | C6: =E13 -> 0
B7: 지출 | C7: =H13+I13 -> 0
B8: 잔액 | C8: =C5+C6-C7-E7 -> 0
B10: 구분 | C10: 이월잔액 | E10: 수입 | H10: 지출
C11: 계좌1 | D11: 계좌2 | E11: 주수입 | F11: 기타 | G11: 기타비고 | H11: 고정비 | I11: 계좌(비고정) | J11: 카드(비고정)
B12: 금액
B13: 합계
B15: 카드별 지출 요약
B16: 카드명 | C16: 일시불 | D16: 할부 | E16: 합계
B17: 하나 알뜰 체크
B18: 하나 신용
B19: 현대 신용
B20: 하나 시코르
B21: 합계
B23: 고정 지출
B24: 구분 | C24: 분류 | D24: 항목 | E24: 지출
B25: 고정비
B40: 합계 | E40: =SUM(E25:E39) -> 0
B42: 지출 - 신용카드 할부
B43: 회차 | C43: 항목 | D43: 금액 | E43: 지불방식 | F43: 잔액 | G43: 잔여회차 | H43: 총 회차
G44: =H44-B44 -> 0
G45: =H45-B45 -> 0
B48: 할부 합계 | D48: =SUM(D44:D47) -> 0 | E48: 할부 잔액 | F48: =SUM(F44:F47) -> 0
B50: 지출 - 비고정비
B51: 날짜 | C51: 항목 | D51: 지불 내용 | E51: 금액 | F51: 지불방식
B52: 비고정비 합계 | F52: 카드 OR 계좌 | G52: 비고
B53: 45326 | C53: 구매 | D53: 로봇 청소기 | E53: 500000 | F53: 계좌
B54: 45333 | C54: 설 용돈 | D54: 엄마 | E54: 300000 | F54: 계좌
B55: 45346 | C55: 축의금 | D55: 윤혜 언니 | E55: 100000 | F55: 계좌
B56: 45349 | C56: 운전교육 | D56: 기능 추가 교육 | E56: 120000 | F56: 계좌

Sheet 8월
E2: 직접입력 | F2: 직접동일입력 | G2: 그 외 자동 연동 | P2: 계획
B4: 요약 | E4: 저축
B5: 이월잔액 | C5: =C13 -> 0
B6: 수입 | C6: =E13 -> 0
B7: 지출 | C7: =H13+I13 -> 0
B8: 잔액 | C8: =C5+C6-C7-E7 -> 0
B10: 구분 | C10: 이월잔액 | E10: 수입 | H10: 지출
C11: 계좌1 | D11: 계좌2 | E11: 주수입 | F11: 기타 | G11: 기타비고 | H11: 고정비 | I11: 계좌(비고정) | J11: 카드(비고정)
B12: 금액
B13: 합계
B15: 카드별 지출 요약
B16: 카드명 | C16: 일시불 | D16: 할부 | E16: 합계
B17: 하나 알뜰 체크
B18: 하나 신용
B19: 현대 신용
B20: 하나 시코르
B21: 합계
B23: 고정 지출
B24: 구분 | C24: 분류 | D24: 항목 | E24: 지출
B25: 고정비
B40: 합계 | E40: =SUM(E25:E39) -> 0
B42: 지출 - 신용카드 할부
B43: 회차 | C43: 항목 | D43: 금액 | E43: 지불방식 | F43: 잔액 | G43: 잔여회차 | H43: 총 회차
G44: =H44-B44 -> 0
G45: =H45-B45 -> 0
B48: 할부 합계 | D48: =SUM(D44:D47) -> 0 | E48: 할부 잔액 | F48: =SUM(F44:F47) -> 0
B50: 지출 - 비고정비
B51: 날짜 | C51: 항목 | D51: 지불 내용 | E51: 금액 | F51: 지불방식
B52: 비고정비 합계 | F52: 카드 OR 계좌 | G52: 비고
B53: 45326 | C53: 구매 | D53: 로봇 청소기 | E53: 500000 | F53: 계좌
B54: 45333 | C54: 설 용돈 | D54: 엄마 | E54: 300000 | F54: 계좌
B55: 45346 | C55: 축의금 | D55: 윤혜 언니 | E55: 100000 | F55: 계좌
B56: 45349 | C56: 운전교육 | D56: 기능 추가 교육 | E56: 120000 | F56: 계좌

Sheet 9월
E2: 직접입력 | F2: 직접동일입력 | G2: 그 외 자동 연동 | P2: 계획
B4: 요약 | E4: 저축
B5: 이월잔액 | C5: =C13 -> 0
B6: 수입 | C6: =E13 -> 0
B7: 지출 | C7: =H13+I13 -> 0
B8: 잔액 | C8: =C5+C6-C7-E7 -> 0
B10: 구분 | C10: 이월잔액 | E10: 수입 | H10: 지출
C11: 계좌1 | D11: 계좌2 | E11: 주수입 | F11: 기타 | G11: 기타비고 | H11: 고정비 | I11: 계좌(비고정) | J11: 카드(비고정)
B12: 금액
B13: 합계
B15: 카드별 지출 요약
B16: 카드명 | C16: 일시불 | D16: 할부 | E16: 합계
B17: 하나 알뜰 체크
B18: 하나 신용
B19: 현대 신용
B20: 하나 시코르
B21: 합계
B23: 고정 지출
B24: 구분 | C24: 분류 | D24: 항목 | E24: 지출
B25: 고정비
B40: 합계 | E40: =SUM(E25:E39) -> 0
B42: 지출 - 신용카드 할부
B43: 회차 | C43: 항목 | D43: 금액 | E43: 지불방식 | F43: 잔액 | G43: 잔여회차 | H43: 총 회차
G44: =H44-B44 -> 0
G45: =H45-B45 -> 0
B48: 할부 합계 | D48: =SUM(D44:D47) -> 0 | E48: 할부 잔액 | F48: =SUM(F44:F47) -> 0
B50: 지출 - 비고정비
B51: 날짜 | C51: 항목 | D51: 지불 내용 | E51: 금액 | F51: 지불방식
B52: 비고정비 합계 | F52: 카드 OR 계좌 | G52: 비고
B53: 45326 | C53: 구매 | D53: 로봇 청소기 | E53: 500000 | F53: 계좌
B54: 45333 | C54: 설 용돈 | D54: 엄마 | E54: 300000 | F54: 계좌
B55: 45346 | C55: 축의금 | D55: 윤혜 언니 | E55: 100000 | F55: 계좌
B56: 45349 | C56: 운전교육 | D56: 기능 추가 교육 | E56: 120000 | F56: 계좌

Sheet 10월
E2: 직접입력 | F2: 직접동일입력 | G2: 그 외 자동 연동 | P2: 계획
B4: 요약 | E4: 저축
B5: 이월잔액 | C5: =C13 -> 0
B6: 수입 | C6: =E13 -> 0
B7: 지출 | C7: =H13+I13 -> 0
B8: 잔액 | C8: =C5+C6-C7-E7 -> 0
B10: 구분 | C10: 이월잔액 | E10: 수입 | H10: 지출
C11: 계좌1 | D11: 계좌2 | E11: 주수입 | F11: 기타 | G11: 기타비고 | H11: 고정비 | I11: 계좌(비고정) | J11: 카드(비고정)
B12: 금액
B13: 합계
B15: 카드별 지출 요약
B16: 카드명 | C16: 일시불 | D16: 할부 | E16: 합계
B17: 하나 알뜰 체크
B18: 하나 신용
B19: 현대 신용
B20: 하나 시코르
B21: 합계
B23: 고정 지출
B24: 구분 | C24: 분류 | D24: 항목 | E24: 지출
B25: 고정비
B40: 합계 | E40: =SUM(E25:E39) -> 0
B42: 지출 - 신용카드 할부
B43: 회차 | C43: 항목 | D43: 금액 | E43: 지불방식 | F43: 잔액 | G43: 잔여회차 | H43: 총 회차
G44: =H44-B44 -> 0
G45: =H45-B45 -> 0
B48: 할부 합계 | D48: =SUM(D44:D47) -> 0 | E48: 할부 잔액 | F48: =SUM(F44:F47) -> 0
B50: 지출 - 비고정비
B51: 날짜 | C51: 항목 | D51: 지불 내용 | E51: 금액 | F51: 지불방식
B52: 비고정비 합계 | F52: 카드 OR 계좌 | G52: 비고
B53: 45326 | C53: 구매 | D53: 로봇 청소기 | E53: 500000 | F53: 계좌
B54: 45333 | C54: 설 용돈 | D54: 엄마 | E54: 300000 | F54: 계좌
B55: 45346 | C55: 축의금 | D55: 윤혜 언니 | E55: 100000 | F55: 계좌
B56: 45349 | C56: 운전교육 | D56: 기능 추가 교육 | E56: 120000 | F56: 계좌

Sheet 11월
E2: 직접입력 | F2: 직접동일입력 | G2: 그 외 자동 연동 | P2: 계획
B4: 요약 | E4: 저축
B5: 이월잔액 | C5: =C13 -> 0
B6: 수입 | C6: =E13 -> 0
B7: 지출 | C7: =H13+I13 -> 0
B8: 잔액 | C8: =C5+C6-C7-E7 -> 0
B10: 구분 | C10: 이월잔액 | E10: 수입 | H10: 지출
C11: 계좌1 | D11: 계좌2 | E11: 주수입 | F11: 기타 | G11: 기타비고 | H11: 고정비 | I11: 계좌(비고정) | J11: 카드(비고정)
B12: 금액
B13: 합계
B15: 카드별 지출 요약
B16: 카드명 | C16: 일시불 | D16: 할부 | E16: 합계
B17: 하나 알뜰 체크
B18: 하나 신용
B19: 현대 신용
B20: 하나 시코르
B21: 합계
B23: 고정 지출
B24: 구분 | C24: 분류 | D24: 항목 | E24: 지출
B25: 고정비
B40: 합계 | E40: =SUM(E25:E39) -> 0
B42: 지출 - 신용카드 할부
B43: 회차 | C43: 항목 | D43: 금액 | E43: 지불방식 | F43: 잔액 | G43: 잔여회차 | H43: 총 회차
G44: =H44-B44 -> 0
G45: =H45-B45 -> 0
B48: 할부 합계 | D48: =SUM(D44:D47) -> 0 | E48: 할부 잔액 | F48: =SUM(F44:F47) -> 0
B50: 지출 - 비고정비
B51: 날짜 | C51: 항목 | D51: 지불 내용 | E51: 금액 | F51: 지불방식
B52: 비고정비 합계 | F52: 카드 OR 계좌 | G52: 비고
B53: 45326 | C53: 구매 | D53: 로봇 청소기 | E53: 500000 | F53: 계좌
B54: 45333 | C54: 설 용돈 | D54: 엄마 | E54: 300000 | F54: 계좌
B55: 45346 | C55: 축의금 | D55: 윤혜 언니 | E55: 100000 | F55: 계좌
B56: 45349 | C56: 운전교육 | D56: 기능 추가 교육 | E56: 120000 | F56: 계좌

Sheet 12월
E2: 직접입력 | F2: 직접동일입력 | G2: 그 외 자동 연동 | P2: 계획
B4: 요약 | E4: 저축
B5: 이월잔액 | C5: =C13 -> 0
B6: 수입 | C6: =E13 -> 0
B7: 지출 | C7: =H13+I13 -> 0
B8: 잔액 | C8: =C5+C6-C7-E7 -> 0
B10: 구분 | C10: 이월잔액 | E10: 수입 | H10: 지출
C11: 계좌1 | D11: 계좌2 | E11: 주수입 | F11: 기타 | G11: 기타비고 | H11: 고정비 | I11: 계좌(비고정) | J11: 카드(비고정)
B12: 금액
B13: 합계
B15: 카드별 지출 요약
B16: 카드명 | C16: 일시불 | D16: 할부 | E16: 합계
B17: 하나 알뜰 체크
B18: 하나 신용
B19: 현대 신용
B20: 하나 시코르
B21: 합계
B23: 고정 지출
B24: 구분 | C24: 분류 | D24: 항목 | E24: 지출
B25: 고정비
B40: 합계 | E40: =SUM(E25:E39) -> 0
B42: 지출 - 신용카드 할부
B43: 회차 | C43: 항목 | D43: 금액 | E43: 지불방식 | F43: 잔액 | G43: 잔여회차 | H43: 총 회차
G44: =H44-B44 -> 0
G45: =H45-B45 -> 0
B48: 할부 합계 | D48: =SUM(D44:D47) -> 0 | E48: 할부 잔액 | F48: =SUM(F44:F47) -> 0
B50: 지출 - 비고정비
B51: 날짜 | C51: 항목 | D51: 지불 내용 | E51: 금액 | F51: 지불방식
B52: 비고정비 합계 | F52: 카드 OR 계좌 | G52: 비고
B53: 45326 | C53: 구매 | D53: 로봇 청소기 | E53: 500000 | F53: 계좌
B54: 45333 | C54: 설 용돈 | D54: 엄마 | E54: 300000 | F54: 계좌
B55: 45346 | C55: 축의금 | D55: 윤혜 언니 | E55: 100000 | F55: 계좌
B56: 45349 | C56: 운전교육 | D56: 기능 추가 교육 | E56: 120000 | F56: 계좌
